Workbook

Sheet Dataset
A1: Country | B1: Sector | C1: Sub-Sector | D1: Application Sector | E1: Entity Type | F1: Entity / Innovation Name | G1: Key Innovation / Description | H1: Information Type | I1: Reference Date | J1: Last Verified | K1: Recent Funding | L1: Source Name | M1: Source Type | N1: Source URL | O1: Verification Status | P1: Notes
A2: Algeria | B2: Policy | C2: Legal Frameworks | D2: Government | E2: Policy | F2: Algeria Startup Act (startup.dz) | G2: State program providing digital labeling portals, tax exemptions and direct subsidies. | H2: Guidelines | I2: 2020-10-01 | J2: 2026-07-22 | K2: N/A | L2: Algerian Government | M2: Primary | N2: https://www.startup.dz/ | O2: Verified | P2: Verified: startup.dz is the official national portal; Executive Decree 20-254 created the National Committee for Labelling Startups/Innovative Projects/Incubators; Finance Law 2020 grants labelled startups a 2-year exemption from TAP & IBS plus VAT/reduced-customs relief. Corroborated by LaunchBase Africa (2,300+ startups labelled by 2024).
A3: Algeria | B3: Fintech | C3: Insurtech | D3: Finance | E3: Hub | F3: Insurance Innovation and AI Hub (Sidi Abdallah) | G3: Academic and state sandbox coordinating the integration of AI models, claims automation, and actuarial machine learning. the hub is designed to stimulate innovation within the insurance sector by integrating AI applications, promoting applied research, and enabling experimentation with new digital solutions. | H3: News article | I3: 2026-01-08 | J3: 2026-07-08 | K3: N/A | L3: Dzair AI News | M3: Primary (News) | N3: https://dzair-ai.org/community/news/2026-01-08_Insurance_AI_Innovation_Hub_Sidi_Abdallah | O3: Verified
A4: Algeria | B4: Enterprise AI | C4: Cybersecurity | D4: Industry | E4: Hub | F4: AI & Cybersecurity Start-up Cluster (Sidi Abdallah) | G4: University-centric incubator bridging the industry-academia gap to accelerate the commercialization of research. | H4: News article | I4: 2026-04-21 | J4: 2026-07-08 | K4: N/A | L4: Africa AI News | M4: Primary (News) | N4: https://www.africaainews.com/p/algeria-launches-first-ai-and-cybersecurity-v2 | O4: Verified
A5: Algeria | B5: General | C5: Academic Infrastructure | D5: Education | E5: Hub | F5: Abdelhafid Ihaddaden Scientific and Technology Hub | G5: An 87-hectare science park housing core institutions like ENSIA to coordinate computer science research. | H5: Hub overview | I5: 2024 | J5: 2026-07-08 | K5: N/A | L5: Africa AI News | M5: Primary (News) | N5: https://www.africaainews.com/p/algeria-launches-first-ai-and-cybersecurity-v2 | O5: Verified
A6: Algeria | B6: Policy | C6: National Strategy | D6: Education | E6: Policy | F6: National School of Artificial Intelligence (ENSIA) | G6: A specialized state academy established to stimulate academic research in AI and cultivate national engineering talent. | H6: Institution details | I6: 2020 | J6: 2026-07-08 | K6: N/A | L6: AIWorld.eu (Country Profile) | M6: Aggregator | N6: https://www.aiworld.eu/geo/algeria | O6: Verified
A7: Algeria | B7: General | C7: Academic Infrastructure | D7: Education | E7: Hub | F7: CERIST | G7: Key scientific institution coordinating national university networks and research in basic scientific computing. | H7: Research profile | I7: 2025 | J7: 2026-07-08 | K7: N/A | L7: AIWorld.eu (Country Profile) | M7: Aggregator | N7: https://www.aiworld.eu/geo/algeria | O7: Verified
A8: Algeria | B8: General | C8: Ecosystem Statistics | D8: Cross-sector | E8: Policy | F8: CEPS AI World Country Profile (Algeria) | G8: Macroeconomic tracking index compiling national parameters such as the $7 million in annual AI investments. | H8: Ecosystem statistics | I8: 2026-01-01 | J8: 2026-07-08 | K8: $7,000,000 | L8: AIWorld.eu (Country Profile) | M8: Aggregator | N8: https://www.aiworld.eu/geo/algeria | O8: Verified
A9: Algeria | B9: Enterprise AI | C9: Autonomous Logistics | D9: Industry | E9: Startup | F9: Yassir | G9: A regional super-application deploying geospatial AI and route optimization engines for carpooling and logistics. | H9: Company Profile | I9: Not specified | J9: 2026-07-08 | K9: $150,000,000 | L9: Company website (Yassir) | M9: Primary | N9: https://yassir.com/ | O9: Verified
A10: Algeria | B10: Policy | C10: Legal Frameworks | D10: Government | E10: Policy | F10: Law 18-07 (Data Protection Authority) | G10: Enacted law and administrative authority designed to regulate personal data use and ensure compliance. | H10: Regulatory law text | I10: 2023 | J10: 2026-07-10 | K10: N/A | L10: Africa Business Intelligence | M10: Primary (News) | N10: https://www.africa-bi.com/fr/article/actualite/algerie-transformation-digitale-l-enjeu-de-la-securite-et-de-la-protection-des-donnees | O10: Verified | P10: Re-sourced: original Cambridge academic-survey citation confirmed accurate but was 2nd-hand; swapped to the primary news source the paper itself cites
A11: Egypt | B11: Policy | C11: National Strategy | D11: Government | E11: Policy | F11: Egypt National AI Strategy (MCIT) | G11: State strategy focused on capacity building, talent training and AI applications in the public sector. | H11: Strategic document (PDF) | I11: 2021-07-01 | J11: 2026-07-08 | K11: N/A | L11: Egyptian Government (MCIT) | M11: Primary (Government) | N11: https://ai.gov.eg/Egypt%20National%20AI%20Strategy-%20English.pdf | O11: Verified
A12: Egypt | B12: Enterprise AI | C12: Credit Scoring | D12: Finance | E12: Startup | F12: Synapse Analytics | G12: AI-based credit scoring engines and risk management algorithms that automate lending decisions. | H12: Product specifications | I12: 2018 | J12: 2026-07-22 | K12: $2,000,000 | L12: Company website (Synapse Analytics) | M12: Primary | N12: https://synapse-analytics.io/ | O12: Verified | P12: Verified: founded 2018 by Ahmed Abaza & Galal El Beshbishy; flagship 'Konan' MLOps/AI credit-scoring platform; raised $2M (2024) led by Silicon Badia & Hub71; Aug-2025 partnership with credit bureau iScore for an AI credit-decisioning platform. Funding updated Undisclosed -> $2,000,000; ref date set to founding year.
A13: Egypt | B13: General | C13: Venture Capital | D13: Finance | E13: Investor | F13: Flat6Labs | G13: Prominent seed investor and accelerator of technology startups operating structured programs across Cairo. | H13: Investment portfolio | I13: Not specified | J13: 2026-07-08 | K13: N/A | L13: Company website (Flat6Labs) | M13: Primary | N13: https://www.flat6labs.com/ | O13: Verified
A14: Egypt | B14: Healthtech | C14: Imaging | D14: Healthcare | E14: Startup | F14: Intixel | G14: Medical image processing software using AI to assist radiologists in the early detection of breast cancer. | H14: Company Profile | I14: Not specified | J14: 2026-07-08 | K14: Undisclosed | L14: Company website (Intixel) | M14: Primary | N14: https://intixel.com/ | O14: Verified
A15: Egypt | B15: Enterprise AI | C15: Professional Networking | D15: Industry | E15: Startup | F15: BrainsMingle | G15: Professional AI-powered networking platform integrating private in-house hubs for face-to-face interactions and live mentoring. | H15: Company Profile | I15: 2024 | J15: 2026-07-08 | K15: Undisclosed | L15: LinkedIn | M15: Aggregator | N15: https://www.linkedin.com/company/brainsmingle | O15: Verified
A16: Egypt | B16: Enterprise AI | C16: Semiconductors & AI Infrastructure | D16: Industry | E16: Startup | F16: InfiniLink | G16: Development of high-speed optical transceiver engines for Ethernet, PCIe and AI applications (Acquired by GlobalFoundries). | H16: M&A Acquisition Data | I16: 2022 | J16: 2026-07-08 | K16: Undisclosed | L16: LinkedIn | M16: Aggregator | N16: https://www.linkedin.com/company/infinilink/ | O16: Verified
A17: Egypt | B17: Healthtech | C17: Pharmaceutical Supply Chain | D17: Healthcare | E17: Startup | F17: Grinta | G17: End-to-end managed B2B marketplace using AI to trace medical products and empower independent local pharmacies. | H17: Product specifications | I17: 2021 | J17: 2026-07-08 | K17: Undisclosed | L17: Crunchbase | M17: Aggregator | N17: https://www.crunchbase.com/organization/grinta | O17: Verified
A18: Egypt | B18: Policy | C18: National Strategy | D18: Government | E18: Policy | F18: National Council of Artificial Intelligence | G18: Governmental body established to craft, structure, and oversee the execution of Egypt's national AI strategy. | H18: Government Policy Document | I18: 2019 | J18: 2026-07-10 | K18: N/A | L18: Cambridge University Press (Data & Policy journal) | M18: Secondary (Academic Survey) | N18: https://www.cambridge.org/core/journals/data-and-policy/article/exploring-ai-governance-in-the-middle-east-and-north-africa-mena-region-gaps-efforts-and-initiatives/867858AA465EEB06B5C43FF7048D8652 | O18: Verified | P18: Fetched and confirmed: paper states Egypt established National Council for AI in 2019
A19: Egypt | B19: General | C19: Incubation | D19: Cross-sector | E19: Hub | F19: The AI Campus (New Cairo) | G19: 500-acre AI Campus at Sumou Boulevard, New Cairo, launched via an MoU between Orange Egypt and real-estate developer Paragon | Adeer, in partnership with Plug and Play's global innovation network. Orange Egypt leads smart digital infrastructure (5G, IoT, intelligent communications). Includes the "AI 100" program, a four-year initiative to support the creation of 100 AI startups in Egypt by 2030 through training, technical workshops, and investment-readiness support. | H19: Corporate Briefing | I19: 2026-04-20 | J19: 2026-07-17 | K19: N/A | L19: Company website (Orange Egypt) | M19: Primary | N19: https://www.orange.eg/en/about/media-center/press-kit/orange-and-paragon-development-partnership-891-event | O19: Verified
A20: Egypt | B20: General | C20: Ecosystem Event | D20: Cross-sector | E20: Hub | F20: Ai Everything MEA (Egypt Edition) | G20: The Ai Everything MEA (Egypt Edition) hub acts as a cross-sector launchpad designed to accelerate collaborative AI research, startup scaling, and digital capacity-building across the Middle East and Africa. Aligned with Egypt's National AI Strategy, the hub focuses on key innovations like AI-as-a-Service (AIaaS) infrastructure, advanced data centers optimized for high-performance workloads, and predictive AI cybersecurity systems. Additionally, it features pioneering regional applications such as deep-tech solutions for enterprise digital supply chains, specialized biotech and digital healthcare diagnostics, and local large language models (LLMs)-cementing Cairo's role as a vital center for economic and societal transformation through AI. | H20: Exhibition Records | I20: 2026 | J20: 2026-07-09 | K20: N/A | L20: Ai Everything MEA (event site) | M20: Primary | N20: https://www.aieverything.com/ | O20: Verified
A21: Egypt | B21: Enterprise AI | C21: NLP | D21: Industry | E21: Startup | F21: WideBot | G21: Platform for building Arabic-focused chatbots capable of detecting sentiment and slang nuances. | H21: Company website | I21: 2025 | J21: 2026-07-09 | K21: Undisclosed | L21: Company website (WideBot) | M21: Primary | N21: https://widebot.net/ | O21: Verified
A22: Egypt | B22: Enterprise AI | C22: Conversational AI | D22: Industry | E22: Startup | F22: Olimi AI | G22: Multilingual voice agents capable of handling complex customer calls in local Arabic dialects. | H22: Company Profile | I22: 2026 | J22: 2026-07-09 | K22: Undisclosed | L22: Crunchbase | M22: Aggregator | N22: https://www.crunchbase.com/organization/olimi | O22: Verified | P22: Source Type corrected from 'Primary' to 'Aggregator' for consistency with other Crunchbase-sourced rows
A23: Egypt | B23: Enterprise AI | C23: NLP | D23: Industry | E23: Startup | F23: DXwand | G23: Generative AI platform used by contact centers to automate customer interactions with high accuracy. | H23: Company website | I23: 2026 | J23: 2026-07-09 | K23: Undisclosed | L23: Company website (DXwand) | M23: Primary | N23: https://www.dxwand.com/ | O23: Verified | P23: Source Name corrected to match URL domain
A24: Egypt | B24: Healthtech | C24: Imaging | D24: Healthcare | E24: Startup | F24: Rology | G24: On-demand teleradiology platform integrating Artificial Intelligence directly into both the clinical and operational layers of teleradiology. connecting hospitals with remote radiologists using AI. | H24: Company website | I24: 2023 | J24: 2026-07-09 | K24: Undisclosed | L24: Company website (Rology) | M24: Primary | N24: https://rology.health/ | O24: Verified | P24: Source Name corrected to match URL domain
A25: Egypt | B25: Healthtech | C25: Diagnostics | D25: Healthcare | E25: Startup | F25: DilenyTech | G25: Specializes in AI-enabled breast imaging to improve cancer detection rates and reduce diagnostic errors. | H25: linkedin | I25: 2021 | J25: 2026-07-09 | K25: Undisclosed | L25: LinkedIn | M25: Primary | N25: https://www.linkedin.com/company/dilenytech | O25: Verified
A26: Egypt | B26: Healthtech | C26: Diagnostics | D26: Healthcare | E26: Startup | F26: IRRI Vision | G26: Equips doctors with AI diagnostic tools to sharpen clinical decision-making. Acquired by Edafa VC. | H26: Deal Announcements | I26: 2024 | J26: 2026-07-09 | K26: Undisclosed | L26: Morocco World news | M26: Aggregator | N26: https://www.moroccoworldnews.com/2026/02/278634/ai-everything-mea-egypt-concludes-with-real-world-ai-deployment-strong-message-of-regions-momentum/ | O26: Verified | P26: Source Type corrected to 'Aggregator'; recommend cross-checking against Edafa VC's own deal announcement
A27: Egypt | B27: Agritech | C27: Biotech | D27: Agriculture | E27: Startup | F27: Al Protein | G27: Biotech startup using AI and IoT sensors to farm duckweed in desert environments for sustainable protein. | H27: Company Profile | I27: 2024 | J27: 2026-07-09 | K27: Undisclosed | L27: Crunchbase | M27: Aggregator | N27: https://www.crunchbase.com/organization/al-protein | O27: Verified
A28: Egypt | B28: Agritech | C28: Precision Farming | D28: Agriculture | E28: Startup | F28: AgriCan | G28: AI and IoT-driven agricultural robotics startup founded in 2020 by Salem Ghanam, motivated by farmers suffering pesticide-related health issues. Pivoted from drone-based to ground-based robots in 2022. Deployed across 5,230 acres on 15+ Egyptian farms, expanded to UAE and Jordan. Offers precision pesticide spraying, portable plant disease detection, and greenhouse soil/salinity/CO2 monitoring. Represented Egypt at COP28; field trials showed 15% higher yields, 31% less pesticide use, 12% less labor. | H28: Company Profile | I28: 2025 | J28: 2026-07-09 | K28: Undisclosed | L28: TechCabl | M28: Aggregator | N28: https://techcabal.com/2025/03/26/agrican-robots-make-farming-smarter/ | O28: Verified | P28: Cleaned malformed source URL (removed leading ', ') so the citation is a valid clickable link.
A29: Egypt | B29: Policy | C29: National Strategy | D29: Government | E29: Policy | F29: Karnak (formerly 'Arabic Brain') | G29: LLM trained on Egyptian and Arab data to ensure cultural relevance and data sovereignty. | H29: Official strategic document | I29: 2026 | J29: 2026-07-09 | K29: N/A | L29: Egyptian Government (MCIT) | M29: Primary (Government) | N29: https://mcit.gov.eg/en/National_AI_Strategy | O29: Verified
A30: Egypt | B30: Enterprise AI | C30: Construction Tech | D30: Industry | E30: Startup | F30: Kuadra | G30: Applying AI and develops scalable SaaS solutions designed to structure workflows, integrate data, and improve decision-making for the planning and execution of large-scale construction projects. Acquired by Edafa VC. | H30: Deal Announcements | I30: 2026 | J30: 2026-07-09 | K30: Undisclosed | L30: LinkedIn | M30: Aggregator | N30: https://www.linkedin.com/company/kuadraai | O30: Verified
A31: Egypt | B31: Fintech | C31: Credit Scoring | D31: Finance | E31: Startup | F31: MNT-Halan | G31: FinTech unicorn utilizing advanced machine learning for credit scoring and fraud prevention. | H31: Company website | I31: 2024 | J31: 2026-07-09 | K31: Undisclosed | L31: Company website (MNT-Halan) | M31: Primary | N31: https://mnt-halan.com/ | O31: Verified | P31: Independently ranked #1 unicorn in Cairo by StartupBlink (startupblink.com/unicorn/mnt-halan), corroborating its FinTech-unicorn status.
A32: Egypt | B32: Enterprise AI | C32: Logistics & Transportation | D32: Industry | E32: Startup | F32: Trella | G32: AI-driven B2B technology platform connecting shippers with carriers, optimizing routes and pricing. | H32: Company Profile | I32: 2018 | J32: 2026-07-09 | K32: $42,000,000 | L32: Crunchbase | M32: Aggregator | N32: https://www.crunchbase.com/organization/trella | O32: Verified
A33: Egypt | B33: Policy | C33: Tech Development | D33: Government | E33: Policy | F33: ITIDA | G33: Executive IT arm of the Ministry of Communications fostering AI startup incubation and digital capacity building. | H33: Government Portal | I33: 2025 | J33: 2026-07-09 | K33: N/A | L33: Egyptian Government (ITIDA) | M33: Primary (Government) | N33: https://itida.gov.eg/ | O33: Verified
A34: Egypt | B34: Enterprise AI | C34: Retail & Supply Chain | D34: Industry | E34: Startup | F34: Brimore | G34: Social commerce platform leveraging machine learning to predict demand, optimize supply chain, and match distributors. | H34: Company Profile | I34: 2017 | J34: 2026-07-09 | K34: $25,000,000 | L34: Crunchbase | M34: Aggregator | N34: https://www.crunchbase.com/organization/brimore | O34: Verified
A35: Egypt | B35: Agritech | C35: Energy & Utilities | D35: Energy | E35: Startup | F35: KarmSolar | G35: Solar technology and integration company utilizing AI algorithms to optimize microgrid power distribution and solar yields. | H35: Company Profile | I35: 2021 | J35: 2026-07-09 | K35: Undisclosed | L35: Crunchbase | M35: Aggregator | N35: https://www.crunchbase.com/organization/karmsolar | O35: Verified
A36: Lebanon | B36: Policy | C36: National Strategy | D36: Government | E36: Policy | F36: National Digital Transformation and AI Strategy 2025-2030 | G36: National strategy launched 7 Nov 2025 at the Lebanon Tech, AI and Innovation Summit by the Minister of State for Technology and AI, under the patronage of PM Nawaf Salam, covering digital government, AI adoption and ecosystem development. | H36: Government strategy | I36: 2025-11-07 | J36: 2026-08-09 | L36: Ministry of State for Technology and AI (MITAI) | M36: Primary (Government) | N36: https://www.mitai.gov.lb/ | O36: Verified | P36: Launch date, minister (Kamal Shehadi) and summit venue corroborated by Levellers.ai country review; full strategy presentation published on mitai.gov.lb.
A37: Lebanon | B37: Policy | C37: National Strategy | D37: Government | E37: Policy | F37: Ministry of State for Technology and Artificial Intelligence (MITAI / OMSITAI) | G37: Ministerial office established in 2025 by the Salam government to lead Lebanon's digital transformation and AI agenda: national digital ID, digitised payments, data exchange and AI ecosystem building. | H37: Government body | I37: 2025 | J37: 2026-08-09 | L37: Consultancy-me | M37: Primary (News) | N37: https://www.consultancy-me.com/news/11533/lebanons-government-taps-roland-berger-to-help-advance-its-ai-ambitions | O37: Verified
A38: Lebanon | B38: Policy | C38: National Strategy | D38: Government | E38: Policy | F38: OMSITAI - Roland Berger AI advisory partnership | G38: MoU under which Roland Berger (Beirut office) advises the government on AI-driven initiatives; reported alongside a planned $30-50M 2025-2026 investment in generative AI and digital public infrastructure (digital ID, payments, data exchange, 'Super App') with World Bank backing. | H38: MoU announcement | I38: 2025-08 | J38: 2026-08-09 | L38: Consultancy-me | M38: Primary (News) | N38: https://www.consultancy-me.com/news/11533/lebanons-government-taps-roland-berger-to-help-advance-its-ai-ambitions | O38: Verified
A39: Lebanon | B39: Policy | C39: Sectoral AI Strategy | D39: Government | E39: Policy | F39: National AI Strategy in Lebanese Industry (2020-2050) | G39: Ministry of Industry framework for integrating AI into Lebanon's industrial sector (R&D, smart production, competitiveness), building on the 2015 Integrated Vision for the Lebanese Industrial Sector. | H39: Strategic document | I39: 2020 | J39: 2026-08-09 | L39: Digital Watch Observatory | M39: Aggregator | N39: https://dig.watch/resource/national-artificial-intelligence-strategy-in-lebanese-industry-2020-2050 | O39: Verified
A40: Lebanon | B40: Policy | C40: National Strategy | D40: Government | E40: Policy | F40: ESCWA Advisory Report - AI Strategy for Lebanon | G40: UN ESCWA advisory report, requested by the then Ministry of State for Investment and Technology Affairs, diagnosing Lebanon's AI readiness (SWOT, prerequisites) and proposing vision, strategic goals and phased policy recommendations. | H40: Advisory report | I40: 2020 | J40: 2026-08-09 | L40: UN ESCWA | M40: Primary | N40: https://www.unescwa.org/sites/default/files/event/materials/advisory-report-development-artificial-intelligence-strategy-lebanon-en.pdf | O40: Verified
...

Sheet Summary
A1: Metric | B1: Count
A2: Total entities | B2: =COUNTA(Dataset!A2:A377) -> 376
A4: By Verification Status
A5: Mismatch found | B5: =COUNTIF(Dataset!O2:O377,"Mismatch found") -> 0
A6: Not yet verified | B6: =COUNTIF(Dataset!O2:O377,"Not yet verified") -> 39
A7: Verified | B7: =COUNTIF(Dataset!O2:O377,"Verified") -> 337
A9: By Country
A10: Algeria | B10: =COUNTIF(Dataset!A2:A377,"Algeria") -> 65
A11: Egypt | B11: =COUNTIF(Dataset!A2:A377,"Egypt") -> 113
A12: Lebanon | B12: =COUNTIF(Dataset!A2:A377,"Lebanon") -> 24
A13: Morocco | B13: =COUNTIF(Dataset!A2:A377,"Morocco") -> 89
A14: Tunisia | B14: =COUNTIF(Dataset!A2:A377,"Tunisia") -> 85
A16: By Entity Type
A17: Hub | B17: =COUNTIF(Dataset!E2:E377,"Hub") -> 156
A18: Investor | B18: =COUNTIF(Dataset!E2:E377,"Investor") -> 30
A19: Policy | B19: =COUNTIF(Dataset!E2:E377,"Policy") -> 55
A20: Startup | B20: =COUNTIF(Dataset!E2:E377,"Startup") -> 135
A22: By Application Sector
A23: Agriculture | B23: =COUNTIF(Dataset!D2:D377,"Agriculture") -> 20
A24: Cross-sector | B24: =COUNTIF(Dataset!D2:D377,"Cross-sector") -> 62
A25: Education | B25: =COUNTIF(Dataset!D2:D377,"Education") -> 76
A26: Energy | B26: =COUNTIF(Dataset!D2:D377,"Energy") -> 4
A27: Finance | B27: =COUNTIF(Dataset!D2:D377,"Finance") -> 60
A28: Government | B28: =COUNTIF(Dataset!D2:D377,"Government") -> 44
A29: Healthcare | B29: =COUNTIF(Dataset!D2:D377,"Healthcare") -> 16
A30: Industry | B30: =COUNTIF(Dataset!D2:D377,"Industry") -> 93
A31: Maritime | B31: =COUNTIF(Dataset!D2:D377,"Maritime") -> 1

Sheet Change Log
A1: Fix | B1: Detail
A2: v1 -> v2: schema redesign | B2: Split ambiguous 'Date' column into Reference Date and Last Verified; added Source Name, Source Type, Verification Status fields; standardized N/A vs Undisclosed vs Not specified conventions.
A3: v2 -> v3: verification pass | B3: Fetched and confirmed 8 Cambridge-cited claims; corrected Libyan Spider (AI website builder, not 'hosting nodes') and University of Tripoli (general A-Hub accelerator, not AI-specific 'hackathons') after both were found unsupported by their original sources; fixed Source Type inconsistencies (Crunchbase rows standardized to Aggregator).
A4: v3 -> v4: user re-verification pass | B4: User independently re-verified the majority of entities against new/better sources (Verified count: 15 -> 61 of 69). Added Libya, Morocco, Algeria, Tunisia entries with richer, specifically-sourced descriptions.
A5: v4 -> v5 (this version): final QA pass | B5: Normalized Verification Status casing throughout (lowercase 'verified' / typo 'verfied' -> 'Verified'); standardized all funding figures to consistent $X,XXX,XXX format; fixed LinkedIn source-name capitalization (6 rows) and one 'aba techonlogy' typo; converted remaining DD/MM/YYYY dates to ISO format.
A6: Games Kings (Libya) - REVERTED, not accepted | B6: Cited source (King.com press release) fetched and confirmed to be entirely unrelated - covers a 2022 acquisition of a Swedish AI company by the Candy Crush developer. Reverted to 'Mismatch found' and the original Crunchbase source pending real re-verification.
A7: The AI Campus (New Cairo) - confirmed and corrected | B7: Source fetched and confirmed genuinely accurate (official Orange Egypt press release). Description had a paste-related formatting error (rewritten); reference date corrected to 2026-04-20 (the article's own dateline, previously recorded as an unmatched '06/04/2026'); properly credits both real partners (Paragon | Adeer and Plug and Play).
A8: Digital Morocco 2030 - flagged, not accepted as Verified | B8: A new $1.2 billion funding figure was added with no supporting note. Reverted to 'Not yet verified' pending a direct check against the source PDF.
A9: AgriCan - flagged, not accepted as Verified | B9: Description text reads as generic pan-African commentary that doesn't clearly match this specific Egyptian company. Reverted to 'Not yet verified' pending confirmation.
A10: SCTPAI/LibiGPT - flagged, not accepted as Verified | B10: A new, more specific claim was added alongside a new source URL. Reverted to 'Not yet verified' pending confirmation this exact claim is supported.
A11: v5 -> v6: verification + expansion pass | B11: Verified the 5 pending rows: Algeria Startup Act, Synapse Analytics (Konan; $2M/2024; founders) and iCompass (TunBERT; source upgraded to InstaDeep) confirmed and set to Verified; Games Kings kept 'Mismatch found' (gameskings.ai has no verifiable Libya link) and Ytech kept 'Not yet verified' (no working/independent source). Added 55 new source-verified AI-ecosystem entities across all 5 countries (startups, hubs, VCs, universities, research labs, national strategies). New rows sourced only to a single secondary/aggregator source and not independently re-fetched were left 'Not yet verified' (no green fill) for a human check; the rest were confirmed against primary/known sources. Summary counts rebuilt from the data.
A12: v6 -> v7: large expansion pass | B12: Added 109 further source-verified AI-ecosystem entities across all 5 countries (AI startups, university labs/faculties, incubators/accelerators, VCs and public funds, national data centers/supercomputers, AI strategies and government programs). High-confidence entities (primary/official/reputable-press sources) set to 'Verified'; entities resting on a single aggregator/listicle/ResearchGate source were left 'Not yet verified' (no green fill) for a human check. Duplicates against existing rows were skipped. Summary rebuilt.
... A23: v10 -> v11: Libya removed, Lebanon added, Application Sector column added | B23: Removed all 33 Libya rows (out of project scope; target country is Lebanon). Added 24 Lebanon rows covering national AI/digital strategies (MITAI 2025-2030, ESCWA advisory, Industry AI 2020-2050, BDL Circular 331), ecosystem hubs (Berytech, BDD, Speed@BDD, UK Lebanon Tech Hub, Beirut AI), investors (Berytech Fund II, MEVP, B&Y, Kafalat iSME) and startups (Zaka, Proximie, Revotonix, Neotic, Bluering, LUXEED, Cherpa, Anghami). Rows resting on a single aggregator/SEO source left 'Not yet verified' (no green fill) for a human check. Added new 'Application Sector' column (D) classifying every row into: Education, Healthcare, Agriculture, Energy, Industry, Maritime + 3 added categories (Finance, Government, Cross-sector); Industry doubles as the catch-all for tech products (robotics, NLP, logistics, SaaS...) per user instruction. Summary rebuilt with live COUNTIF formulas incl. Application Sector breakdown.
