Workbook

Sheet Dataset
A1: Country | B1: Sector | C1: Sub-Sector | D1: Entity Type | E1: Maturity | F1: Entity / Innovation Name | G1: Key Innovation / Description | H1: Information Type | I1: Reference Date | J1: Last Verified | K1: Recent Funding | L1: Source Name | M1: Source Type | N1: Source URL | O1: Verification Status | P1: Notes
A2: Algeria | B2: Industry | C2: Developer & AI community | D2: Community/Association | E2: Established | F2: GDG Algiers (Google Developer Group Algiers & DevFest Algiers) | G2: Long-running Google Developer Group chapter in Algiers running DevFest Algiers and AI-focused programming ('Build with AI', AiFest at ENSIA via GDG on Campus), one of Algeria's largest volunteer tech communities training students in ML and cloud technologies. | H2: Community profile | I2: 2024 | J2: 2026-08-05 | L2: Google Developer Groups | M2: Primary | N2: https://gdg.community.dev/gdg-algiers/ | O2: Verified | P2: Official Google community platform page plus gdgalgiers.com DevFest 2024 site and GDG-on-Campus ENSIA AI event listings. [Added 2026-08-05 expansion pass]
A3: Algeria | B3: Education | C3: Machine learning community conference | D3: Community/Association | E3: Established | F3: IndabaX Algeria | G3: Algerian chapter of the Deep Learning Indaba movement 'Strengthening African Machine Learning', holding locally organized IndabaX Algeria editions (2022, 2023 and a listed 2025 edition) that gather students and researchers for ML/AI tutorials and talks. | H3: Event | I3: 2025 | J3: 2026-08-05 | L3: Deep Learning Indaba | M3: Primary | N3: https://deeplearningindaba.com/2025/indabax/algeria/ | O3: Verified | P3: Listed on the official Deep Learning Indaba site (2023 and 2025 IndabaX pages) plus dedicated indabaxalgeria.com site; 2025 page has limited detail. [Added 2026-08-05 expansion pass] [Merge re-audit 2026-08] Ecosystem Type corrected: 'Conference/Summit' -> 'Community/Association'. Was Conference/Summit - same pattern as IndabaX Tunisia: a recurring local chapter of the Deep Learning Indaba movement gathering students/researchers, not a single conference.
A4: Algeria | B4: Industry | C4: AI Skills Training | D4: Community/Association | E4: Established | F4: Skills Centers (Scale Centers) network | G4: Government network of seven free regional digital-skills centres (Algiers, Oran, Annaba, Setif, Chlef, Saida, Adrar) training youth in AI, IoT, cybersecurity and cloud. | H4: News article | I4: 2025 | J4: 2026-07-22 | L4: We Are Tech Africa | M4: Primary (News) | N4: https://www.wearetech.africa/en/fils-uk/news/public-management/algeria-launches-setif-skills-center-to-boost-youth-innovation-with-free-ai-and-ict-training | O4: Verified | P4: Corroborated by TechAfrica News. [Reclassified 2026-08-01] Old Sector: 'General' -> New: 'Energy, Agriculture, Maritime, Health, Industry, Education'. Old Entity Type: 'Hub' -> New Ecosystem Type: 'Community/Association'. [Refined 2026-08-02] Sector forced to single label 'Industry' (was multi-sector: Energy, Agriculture, Maritime, Health, Industry, Education). Maturity inferred as 'Established' (structural-type).
A5: Algeria | B5: Industry | C5: Pan-African Startup & AI Conference | D5: Conference/Summit | E5: Established | F5: African Startup Conference (Algiers) | G5: Annual pan-African startup conference at CIC Algiers; 3rd edition (Dec 2024) put AI at its heart with 45 ministers, 800+ investors/startups, an AI tech exhibition and an African VC Summit. | H5: News article | I5: 2024-12 | J5: 2026-07-22 | L5: AL24 News | M5: Primary (News) | N5: https://al24news.dz/en/african-start-up-conference-ai-at-the-heart-of-3rd-edition-in-algiers/ | O5: Verified | P5: [Reclassified 2026-08-01] Old Sector: 'General' -> New: 'Energy, Agriculture, Maritime, Health, Industry, Education'. Old Entity Type: 'Hub' -> New Ecosystem Type: 'Conference/Summit'. [Refined 2026-08-02] Sector forced to single label 'Industry' (was multi-sector: Energy, Agriculture, Maritime, Health, Industry, Education). Maturity inferred as 'Established' (structural-type).
A6: Algeria | B6: Industry | C6: Tech Conference (AI/Cloud/Cyber) | D6: Conference/Summit | E6: Established | F6: Algeria 2.0 | G6: Long-running Algerian tech event (13th edition, 24-28 Nov 2026, Sidi Abdellah Cyberparc) with workshops and hackathons on AI, cloud, cybersecurity, web/mobile and SaaS. | H6: Event page | I6: 2026-11-24 | J6: 2026-07-22 | L6: Algeria 2.0 (official) | M6: Primary | N6: https://algeria20.com/?lang=en | O6: Verified | P6: [Reclassified 2026-08-01] Old Sector: 'General' -> New: 'Energy, Agriculture, Maritime, Health, Industry, Education'. Old Entity Type: 'Hub' -> New Ecosystem Type: 'Hackathons'. [Refined 2026-08-02] Sector forced to single label 'Industry' (was multi-sector: Energy, Agriculture, Maritime, Health, Industry, Education). Maturity inferred as 'Idea-stage' (hackathon-type). [Audit 2026-08-05] Entity Type corrected: 'Hackathons' -> 'Conference/Summit'. [Audit 2026-08-05] Reason: long-running tech conference (13th edition); hackathons are a sub-activity [Audit 2026-08-05] Maturity corrected: 'Idea-stage' -> 'Established'. [Audit 2026-08-05] Reason: 13th-edition long-running event; structural-type
A7: Algeria | B7: Health | C7: E-health innovation competition | D7: Conference/Summit | E7: Early | F7: Algiers Slush'D E-Health Innovation Awards (Roche Algérie x Algeria Venture) | G7: Inaugural Algiers Slush'D health-innovation track co-organized by Roche Algérie and public accelerator Algeria Venture under the patronage of the startups and health ministries; in January 2025 it selected three digital-health startups (Sihatech, Docteur 360, M-Click) from 40 submissions for a dedicated acceleration program. | H7: Event | I7: 2025-01-24 | J7: 2026-08-05 | L7: Algérie Eco | M7: Primary (News) | N7: https://algerie-eco.com/2025/01/24/e-sante-3-startups-algeriennes-recompensees-pour-leur-innovation/ | O7: Verified | P7: Algérie Eco report read directly; also relayed by AllAfrica, naming organizers, jury criteria and the three winners. [Added 2026-08-05 expansion pass]
A8: Algeria | B8: Industry | C8: Tech leadership forum (AI theme) | D8: Conference/Summit | E8: Established | F8: CTO Forum Algeria | G8: Technology leadership forum organized by BoostEvent whose inaugural edition (8-10 May 2023, CIC Abdelatif-Rahal, Algiers) took AI as its opening theme with ~150 exhibitors and speakers including Merouane Debbah on large language models and Algeria Venture's Sid Ali Zerrouki. | H8: Event | I8: 2023-05-08 | J8: 2026-08-05 | L8: Charikati | M8: Primary (News) | N8: https://dzcharikati.net/1e-cto-forum-algeria-lintelligence-artificielle-comme-thematique-inaugurale/ | O8: Verified | P8: Detailed Charikati event report read directly, listing organizers, ministers in attendance and AI program content. [Added 2026-08-05 expansion pass]
A9: Algeria | B9: Industry | C9: National ICT & AI forum | D9: Conference/Summit | E9: Established | F9: Connected Algeria 2025 | G9: Government ICT and digital transformation forum held 6-7 April 2025 at the International Conference Center in Algiers under the Ministry of Post and Telecommunications (Minister Sid Ali Zerrouki), gathering 1,000+ experts; AI was a central theme, with the minister announcing the national AI strategy was in its final drafting phase. | H9: Event | I9: 2025-04-06 | J9: 2026-08-05 | L9: Ouest Tribune | M9: Primary (News) | N9: https://ouest-tribune.dz/connected-algeria-2025-une-plateforme-strategique-pour-la-transformation-numerique-de-lalgerie/ | O9: Verified | P9: Cross-checked Ouest Tribune report with APS closing-session coverage and the official connectedalgeria.dz site. [Added 2026-08-05 expansion pass]
A10: Algeria | B10: Industry | C10: Venture Capital | D10: Funding | E10: Established | F10: Afiya Investments | G10: First venture-capital fund (FCPR) approved by Algeria's market regulator COSOB, managed by Tell Group, financing innovative early/growth-stage startups. | H10: News article | I10: 2025 | J10: 2026-07-27 | K10: Undisclosed | L10: Techpression | M10: Primary (News) | N10: https://techpression.com/algeria-startup-ecosystem-2025-reforms-driving-tech-innovation-and-growth/ | O10: Verified | P10: [Pending verification] AI-specific mandate general. Confirmed via dedicated research pass: Algeria's first COSOB-approved private VC vehicle (FCPR), managed by Tell Markets. Note: AI is not an explicit mandate - general VC vehicle. [Reclassified 2026-08-01] Old Sector: 'General' -> New: 'Energy, Agriculture, Maritime, Health, Industry, Education'. Old Entity Type: 'Investor' -> New Ecosystem Type: 'Funding'. [Refined 2026-08-02] Sector forced to single label 'Industry' (was multi-sector: Energy, Agriculture, Maritime, Health, Industry, Education). Maturity inferred as 'Established' (structural-type).
A11: Algeria | B11: Industry | C11: Venture Capital | D11: Funding | E11: Established | F11: Algerian Startup Fund (ASF) | G11: Public VC company (created Oct 2020 with six public banks) financing labelled Algerian startups, including AI ventures. | H11: Investor profile | I11: 2020-10 | J11: 2026-07-22 | L11: ASF (official) | M11: Primary | N11: https://asf.dz/ | O11: Verified | P11: Bank-backed fintech fund launch confirmed. [Reclassified 2026-08-01] Old Sector: 'Fintech' -> New: 'Energy, Agriculture, Maritime, Health, Industry, Education'. Old Entity Type: 'Investor' -> New Ecosystem Type: 'Funding'. [Refined 2026-08-02] Sector forced to single label 'Industry' (was multi-sector: Energy, Agriculture, Maritime, Health, Industry, Education). Maturity inferred as 'Established' (structural-type).
A12: Algeria | B12: Industry | C12: Public Venture Funding | D12: Funding | E12: Established | F12: Algerie Telecom AI/Cybersecurity/Robotics Fund | G12: State telecom operator's ~1.5bn-dinar (~$11M) fund announced 2025 to invest in AI, cybersecurity and robotics startups. | H12: News | I12: 2025-02 | J12: 2026-07-22 | K12: $11,000,000 | L12: LaunchBase Africa | M12: Primary (News) | N12: https://launchbaseafrica.com/2025/02/18/algeria-bets-big-on-ai-startups-with-new-investment-fund/ | O12: Verified | P12: [Reclassified 2026-08-01] Old Sector: 'General' -> New: 'Industry'. Old Entity Type: 'Investor' -> New Ecosystem Type: 'Funding'. [Refined 2026-08-02] Sector set to 'Industry'. Maturity inferred as 'Established' (structural-type).
A13: Algeria | B13: Industry | C13: Ecosystem Statistics | D13: Funding | E13: Established | F13: CEPS AI World Country Profile (Algeria) | G13: Macroeconomic tracking index compiling national parameters such as the $7 million in annual AI investments. | H13: Ecosystem statistics | I13: 2026-01-01 | J13: 2026-07-08 | K13: $7,000,000 | L13: AIWorld.eu (Country Profile) | M13: Aggregator | N13: https://www.aiworld.eu/geo/algeria | O13: Verified | P13: [Pending verification] Direct AI investments not individually verified. Confirmed via dedicated research pass: real Tunis asset manager; New Era Fund I (EUR7M first close) targets AI, biotech and green tech - AI is one of three sectors, not exclusive focus. [Reclassified 2026-08-01] Old Sector: 'General' -> New: 'Energy, Agriculture, Maritime, Health, Industry, Education'. Old Entity Type: 'Investor' -> New Ecosystem Type: 'Funding'. [Refined 2026-08-02] Sector forced to single label 'Industry' (was multi-sector: Energy, Agriculture, Maritime, Health, Industry, Education). Maturity inferred as 'Established' (structural-type).
A14: Algeria | B14: Industry | C14: Angel Investment Network | D14: Funding | E14: Established | F14: Casbah Business Angels | G14: First independent Algerian business-angel network (launched 2012 by Silicon Valley and Algerian CEOs), providing early-stage funding and mentorship to Algerian tech startups. | H14: Investor profile | I14: 2012 | J14: 2026-07-22 | L14: Gust | M14: Aggregator | N14: https://gust.com/organizations/casbah-business-angels | O14: Verified | P14: Cross-checked with VC4A and MAGNiTT; generalist tech investor. [Reclassified 2026-08-01] Old Sector: 'General' -> New: 'Energy, Agriculture, Maritime, Health, Industry, Education'. Old Entity Type: 'Investor' -> New Ecosystem Type: 'Funding'. [Refined 2026-08-02] Sector forced to single label 'Industry' (was multi-sector: Energy, Agriculture, Maritime, Health, Industry, Education). Maturity inferred as 'Established' (structural-type).
A15: Algeria | B15: Industry | C15: Public Venture Programme / Fund | D15: Funding | E15: Established | F15: National Venture Studio Programme | G15: $600M public-private, five-year programme (Algerian Startup Fund + CERIST + venture studio DeepMinds) to create 1,000+ tech ventures across all 58 provinces. | H15: News article | I15: 2025 | J15: 2026-07-22 | K15: $600,000,000 | L15: Middle East AI News | M15: Primary (News) | N15: https://www.middleeastainews.com/p/algeria-venture-studio-1000-startups | O15: Verified | P15: Cross-verified via DeepMinds press release and BridgeMENA. [Reclassified 2026-08-01] Old Sector: 'General' -> New: 'Energy, Agriculture, Maritime, Health, Industry, Education'. Old Entity Type: 'Investor' -> New Ecosystem Type: 'Funding'. [Refined 2026-08-02] Sector forced to single label 'Industry' (was multi-sector: Energy, Agriculture, Maritime, Health, Industry, Education). Maturity inferred as 'Established' (structural-type).
A16: Algeria | B16: Industry | C16: Startup Competition with AI Track | D16: Hackathons | E16: Idea-stage | F16: Algeria Startup Challenge (ASC) | G16: Largest Algerian open-innovation startup program (created 2018); 7th edition final (24 Nov 2025, Sidi Fredj) with 16 finalists and panels on AI's structuring role in the national economy. | H16: Event page + news | I16: 2025-11-24 | J16: 2026-07-22 | L16: Algeria Startup Challenge (official) | M16: Primary | N16: https://algeriastartupchallenge.com/ | O16: Verified | P16: Official site; venue and AI topics stated. [Reclassified 2026-08-01] Old Sector: 'General' -> New: 'Energy, Agriculture, Maritime, Health, Industry, Education'. Old Entity Type: 'Hub' -> New Ecosystem Type: 'Hackathons'. [Refined 2026-08-02] Sector forced to single label 'Industry' (was multi-sector: Energy, Agriculture, Maritime, Health, Industry, Education). Maturity inferred as 'Idea-stage' (hackathon-type).
A17: Algeria | B17: Industry | C17: Youth AI hackathon (health, energy, smart city themes) | D17: Hackathons | E17: Idea-stage | F17: Artificial Intelligence and Entrepreneurship Hackathon - Algeria 2026 (Sidi Abdellah) | G17: 38-hour national hackathon held 6-8 January 2026 at the Sidi Abdellah Scientific and Technological Hub, organized by 'Meeting of the Youth of Algeria' with the Ministry of Youth and Ministry of Higher Education; themes covered AI for youth mental health, smart waste/renewable-energy technologies and intelligent urban infrastructure. | H17: Event | I17: 2026-01-06 | J17: 2026-08-05 | L17: Université de Khenchela | M17: Primary | N17: https://www.univ-khenchela.dz/en/artificial-intelligence-and-entrepreneurship-hackathon-algeria-2026/ | O17: Verified | P17: Details taken from an official Algerian university announcement page including dates, themes and registration process. [Added 2026-08-05 expansion pass]
A18: Algeria | B18: Education | C18: National AI student competition | D18: Hackathons | E18: Idea-stage | F18: Concours National d'Intelligence Artificielle (Semaine nationale de l'IA 2025, Constantine) | G18: National AI competition launched 23 November 2025 at Université Frères Mentouri Constantine 1 during Algeria's National Week of AI and Scientific Research, gathering 60 innovative AI projects from students, teachers and researchers across the country. | H18: Event | I18: 2025-11-23 | J18: 2026-08-05 | L18: Algérie Presse Service (APS) | M18: Primary (Government) | N18: https://www.aps.dz/fr/algerie/education-et-technologie/mic0nq2g-lancement-d-un-concours-national-d-intelligence-artificielle-avec-la-participation-de-60-projets-innovants | O18: Verified | P18: Confirmed via APS (official state press agency) and corroborated by La Nouvelle République and Le Jour d'Algérie. [Added 2026-08-05 expansion pass]
A19: Algeria | B19: Industry | C19: AI-for-Good Competition | D19: Hackathons | E19: Idea-stage | F19: Djazairia Challenge 2025 - IA for Good | G19: AI-for-impact challenge positioning AI as a development lever for Africa, run with the Printemps numerique organisation. | H19: News article | I19: 2025 | J19: 2026-07-22 | L19: Printemps numerique | M19: Primary | N19: https://www.printempsnumerique.ca/ | O19: Verified | P19: [Pending verification] Run partly by a Canadian partner. [Reclassified 2026-08-01] Old Sector: 'General' -> New: 'Energy, Agriculture, Maritime, Health, Industry, Education'. Old Entity Type: 'Hub' -> New Ecosystem Type: 'Hackathons'. [Refined 2026-08-02] Sector forced to single label 'Industry' (was multi-sector: Energy, Agriculture, Maritime, Health, Industry, Education). Maturity inferred as 'Idea-stage' (hackathon-type). [Web re-verification 2026-08-05] Status 'Not yet verified' -> 'Verified'. Printemps numerique (the cited source org) published a dedicated article on 'Djazairia Challenge 2025 - IA for Good', confirming the AI-for-impact challenge and its framing of AI as a development lever for Africa. Confirming source: https://www.printempsnumerique.ca/nouvelles/article/djazairia-challenge-2025-ia-for-good-quand-lintelligence-artificielle-devient-un-levier-dimpact-pour-lafrique/
A20: Algeria | B20: Agriculture | C20: Agricultural AI hackathon | D20: Hackathons | E20: Idea-stage | F20: Défi de l'Agriculture Hackathon (ENSIA x ENSA) | G20: Three-day national hackathon (2nd edition, June 2025, Algiers) organized by the National Higher School of AI (ENSIA) and the National Higher School of Agronomy with the Jardin d'Essai du Hamma, Mobilis and AI Grid; 125 students in 25 teams built agricultural AI prototypes and produced a first-of-its-kind local dataset of 180,000+ plant images. | H20: Event | I20: 2025-06 | J20: 2026-08-05 | L20: AllAfrica (APS) | M20: Primary (News) | N20: https://fr.allafrica.com/stories/202506260675.html | O20: Verified | P20: APS state-agency report relayed by AllAfrica, including ENSIA director's 180,000-image dataset claim and minister Baddari's attendance. [Added 2026-08-05 expansion pass]
A21: Algeria | B21: Industry | C21: Corporate student tech/AI hackathon | D21: Hackathons | E21: Idea-stage | F21: Huawei Algérie Tech4Connect 2026 Hackathon | G21: First edition of Huawei Algeria's 'Tech4Connect' hackathon for university student teams; winning teams were awarded in March 2026, extending Huawei's ICT talent activities in Algeria beyond its ICT Academy and ICT Competition. | H21: Event | I21: 2026-03-12 | J21: 2026-08-05 | L21: L'Express DZ | M21: Primary (News) | N21: https://www.expressdz.dz/2026/03/12/huawei-algerie-recompense-les-equipes-etudiantes-laureates-du-premier-hackathon-tech4connect-2026/ | O21: Not yet verified | P21: Single national press report found (article page could not be fully fetched); headline confirms first-edition awards by Huawei Algérie in March 2026. [Added 2026-08-05 expansion pass]
A22: Algeria | B22: Industry | C22: Postal / fintech innovation hackathon | D22: Hackathons | E22: Idea-stage | F22: InnovPost Hackathon (Algérie Poste) | G22: First national hackathon of state postal operator Algérie Poste, launched in November 2024 to crowdsource technological innovation (digital payments and postal services) from students and young developers, with a first-edition prize ceremony recognizing winning teams. | H22: Event | I22: 2024-11-12 | J22: 2026-08-05 | L22: Algérie Poste | M22: Primary | N22: https://www.poste.dz/news/s/ceremonie-de-remise-des-prix-de-la-premiere-edition-de-lhackathon-innovpost-2024 | O22: Verified | P22: Official Algérie Poste press page for the INNOVPOST 2024 prize ceremony, corroborated by El Watan and Algérie Patriotique launch coverage (12 Nov 2024). [Added 2026-08-05 expansion pass]
A23: Algeria | B23: Industry | C23: Technology Park Operator & Incubation | D23: Incubator/Accelerator | E23: Established | F23: ANPT (Agence Nationale des Parcs Technologiques) | G23: State agency (est. 2004) operating the 92-ha Sidi Abdellah Technopark and regional technoparks; runs an incubator and the Virtual Incubation Program (VIP); hosts AI-focused events. | H23: Agency profile | I23: 2004 | J23: 2026-07-22 | L23: ANPT (official) | M23: Primary (Government) | N23: https://www.anpt.dz/about | O23: Verified | P23: Distinct from the Sidi Abdallah AI hubs (ANPT is the park operator). [Reclassified 2026-08-01] Old Sector: 'General' -> New: 'Energy, Agriculture, Maritime, Health, Industry, Education'. Old Entity Type: 'Hub' -> New Ecosystem Type: 'Incubator/Accelerator'. [Refined 2026-08-02] Sector forced to single label 'Industry' (was multi-sector: Energy, Agriculture, Maritime, Health, Industry, Education). Maturity inferred as 'Established' (structural-type).
A24: Algeria | B24: Industry | C24: State Accelerator & Fund | D24: Incubator/Accelerator | E24: Established | F24: Algeria Venture (A-Venture) | G24: First state-owned startup accelerator (est. Dec 2020) coaching and financing startups; agreement with SEAF created the $80M Algeria Innovation Funds; co-launched the AventureCloudz AI platform (2026). | H24: News article | I24: 2023-01 | J24: 2026-07-22 | K24: $80,000,000 (fund) | L24: Algerie Eco | M24: Primary (News) | N24: https://algerie-eco.com/2023/01/25/startups-algeria-venture-et-seaf-vont-creer-un-fonds-dinvestissement-dune-valeur-de-80-millions-de-dollars/ | O24: Verified | P24: Confirmed via dedicated research pass: real general entrepreneurship hub (Algiers, 2015) - not AI-specific, description should reflect that. Re-confirmed via dedicated research pass: Algeria's first private accelerator/coworking hub (2015) - correctly NOT categorized as an AI startup. [Reclassified 2026-08-01] Old Sector: 'General' -> New: 'Energy, Agriculture, Maritime, Health, Industry, Education'. Old Entity Type: 'Hub' -> New Ecosystem Type: 'Incubator/Accelerator'. [Refined 2026-08-02] Sector forced to single label 'Industry' (was multi-sector: Energy, Agriculture, Maritime, Health, Industry, Education). Maturity inferred as 'Established' (structural-type).
A25: Algeria | B25: Industry | C25: Venture Studio | D25: Incubator/Accelerator | E25: Established | F25: DeepMinds | G25: Decentralised venture studio and co-lead of Algeria's National Venture Studio Programme, turning national research into market-ready deeptech/AI companies. | H25: Organization profile | I25: 2025 | J25: 2026-07-22 | L25: DeepMinds (official) | M25: Primary | N25: https://deepminds.me/press/A-New-Era-for-Innovation-ASF-CERIST-DeepMinds-Unite-to-Build-1000-Tech-Ventures-Across-Algeria | O25: Verified | P25: [Reclassified 2026-08-01] Old Sector: 'General' -> New: 'Energy, Agriculture, Maritime, Health, Industry, Education'. Old Entity Type: 'Hub' -> New Ecosystem Type: 'Incubator/Accelerator'. [Refined 2026-08-02] Sector forced to single label 'Industry' (was multi-sector: Energy, Agriculture, Maritime, Health, Industry, Education). Maturity inferred as 'Established' (structural-type).
A26: Algeria | B26: Industry | C26: AI Incubator | D26: Incubator/Accelerator | E26: Established | F26: DjazairIA | G26: Algeria's first private incubator entirely dedicated to AI (launched Sept 2025); offers coworking, coaching, fundraising and a partnership with Toronto Metropolitan University's DMZ. | H26: Organization profile | I26: 2025-09-13 | J26: 2026-07-22 | L26: DjazairIA (official) | M26: Primary | N26: https://djazairia.com/incubateur/ | O26: Verified | P26: Confirmed via primary site + Canadian/Algerian press. [Reclassified 2026-08-01] Old Sector: 'General' -> New: 'Energy, Agriculture, Maritime, Health, Industry, Education'. Old Entity Type: 'Hub' -> New Ecosystem Type: 'R&D'. [Refined 2026-08-02] Sector forced to single label 'Education' (was multi-sector: Energy, Agriculture, Maritime, Health, Industry, Education). Maturity inferred as 'Early' (default for Startup/R&D with no funding signal). [Manual fix 2026-08-03, validation pass 2] Entity Type corrected from 'R&D' to 'Incubator/Accelerator'. Was R&D despite its own Sub-Sector explicitly saying 'AI Incubator'. [Audit 2026-08-05] Sector corrected: 'Education' -> 'Industry'. [Audit 2026-08-05] Reason: generic AI incubator -> Industry fallback, consistent with IncubMe/Leancubator [Audit 2026-08-05] Maturity corrected: 'Early' -> 'Established'. [Audit 2026-08-05] Reason: structural type per maturity rule (was left unadjusted after manual entity-type fix)
A27: Algeria | B27: Agriculture | C27: Private Incubation & African Acceleration | D27: Incubator/Accelerator | E27: Established | F27: IncubMe | G27: Private Algiers incubator/accelerator; its AFRICA by IncubMe program supports African entrepreneurs across health, renewable energy, fintech, IoT, ICT and agriculture. | H27: Organization profile | I27: Not specified | J27: 2026-07-22 | L27: IncubMe (official) | M27: Primary | N27: https://incubme.com/ | O27: Verified | P27: Africa cohort cross-checked with Ilboursa; AI one of several verticals. [Reclassified 2026-08-01] Old Sector: 'General' -> New: 'Agriculture'. Old Entity Type: 'Hub' -> New Ecosystem Type: 'Incubator/Accelerator'. [Refined 2026-08-02] Sector set to 'Agriculture'. Maturity inferred as 'Established' (structural-type).
A28: Algeria | B28: Industry | C28: Innovation Hub & Open-Innovation Programs | D28: Incubator/Accelerator | E28: Established | F28: Leancubator | G28: Algiers innovation hub implementing national programs (Kick-Start with Algeria Venture and the Knowledge Economy Ministry), Algeria Startup Challenge and EU-funded incubation; ranked top Algerian incubator in 2025. | H28: Organization profile | I28: 2018 | J28: 2026-07-22 | L28: Leancubator (official) | M28: Primary | N28: https://leancubator.co/programs/ | O28: Verified | P28: Cross-checked with Challenge.ma coverage. [Reclassified 2026-08-01] Old Sector: 'General' -> New: 'Energy, Agriculture, Maritime, Health, Industry, Education'. Old Entity Type: 'Hub' -> New Ecosystem Type: 'Incubator/Accelerator'. [Refined 2026-08-02] Sector forced to single label 'Industry' (was multi-sector: Energy, Agriculture, Maritime, Health, Industry, Education). Maturity inferred as 'Established' (structural-type).
A29: Algeria | B29: Industry | C29: Accelerator / Incubator | D29: Incubator/Accelerator | E29: Established | F29: Sylabs | G29: Algeria's first private startup accelerator and tech hub (founded Dec 2015 in Algiers), providing coworking, incubation and the DZ Acceleration Program. | H29: Company profile | I29: 2015-12 | J29: 2026-07-27 | L29: MENAbytes | M29: Secondary | N29: https://www.menabytes.com/slyabs-algeria-startup-accelerator/ | O29: Verified | P29: Official site lists incubation/acceleration programs. [Reclassified 2026-08-01] Old Sector: 'General' -> New: 'Energy, Agriculture, Maritime, Health, Industry, Education'. Old Entity Type: 'Hub' -> New Ecosystem Type: 'Incubator/Accelerator'. [Refined 2026-08-02] Sector forced to single label 'Industry' (was multi-sector: Energy, Agriculture, Maritime, Health, Industry, Education). Maturity inferred as 'Established' (structural-type).
A30: Algeria | B30: Industry | C30: Data Center / Infrastructure | D30: Other initiatives | E30: Early | F30: AI Data Center in Oran (Akid Lotfi) | G30: Government-backed AI-dedicated data centre whose foundation stone was laid March 2025 in Oran, to be fitted with latest-generation GPUs. | H30: News | I30: 2025-03 | J30: 2026-07-22 | L30: Data Center Dynamics | M30: Primary (News) | N30: https://www.datacenterdynamics.com/en/news/algerian-govt-breaks-ground-on-ai-data-center-in-oran/ | O30: Verified | P30: Oracle hosting role cross-checked via Data Center Dynamics. [Reclassified 2026-08-01] Old Sector: 'Enterprise AI' -> New: 'Energy, Agriculture, Maritime, Health, Industry, Education'. Old Entity Type: 'Hub' -> New Ecosystem Type: 'Other initiatives'. [Refined 2026-08-02] Sector forced to single label 'Industry' (was multi-sector: Energy, Agriculture, Maritime, Health, Industry, Education). Maturity inferred as 'Early' (default for Startup/R&D with no funding signal).
A31: Algeria | B31: Maritime | C31: Customs & port trade facilitation AI | D31: Other initiatives | E31: Early | F31: ALCES - Algerian Customs digital clearance & AI risk-management system | G31: Digital customs information system launched in late 2023 by the Direction Générale des Douanes: online declarations and payments, real-time cargo tracking, and AI-based risk management that analyzes data in real time to detect anomalies and target suspicious import/export operations; over 120,000 declarations processed, with single-window expansion planned for 2025. | H31: Government program | I31: 2025 | J31: 2026-08-05 | L31: Maghreb Émergent | M31: Primary (News) | N31: https://www.maghrebemergent.com/les-douanes-algeriennes-accelerent-leur-transformation-numerique-et-devoilent-alces-un-systeme-qui-revolutionne-les-formalites-commerciales/ | O31: Verified | P31: Details read directly from Maghreb Émergent article; AI risk-targeting and 120,000+ declarations figure stated there. [Added 2026-08-05 expansion pass]
A32: Algeria | B32: Industry | C32: Airport / transport AI | D32: Other initiatives | E32: Early | F32: Algiers Houari Boumediene Airport AI modernization (SGSIA) | G32: SGSIA (Algiers airport management company) announced on 14 September 2025 the integration of AI into airport operations - facial recognition, intelligent gates, body scanners, automated kiosks and contactless travel - with systems going operational in December 2025 to position Algiers as a regional hub. | H32: Corporate AI project | I32: 2025-09-14 | J32: 2026-08-05 | L32: Maghreb Émergent | M32: Primary (News) | N32: https://www.maghrebemergent.com/technologie-de-pointe-laeroport-dalger-adopte-lintelligence-artificielle-pour-ameliorer-ses-services-en-2025/ | O32: Verified | P32: Based on public statements by SGSIA CEO Mokhtar Saïd Mediouni reported by Maghreb Émergent. [Added 2026-08-05 expansion pass]
A33: Algeria | B33: Industry | C33: Sovereign AI/Cloud Developer Platform | D33: Other initiatives | E33: Early | F33: AventureCloudz | G33: Full-stack sovereign AI development platform launched 29 Apr 2026 by Djezzy, Algeria Venture and Taubyte; hosted on Djezzy cloud, offering serverless, databases, storage and AI workflows for Algerian developers. | H33: News article | I33: 2026-04-29 | J33: 2026-07-22 | L33: TechAfrica News | M33: Primary (News) | N33: https://techafricanews.com/2026/05/04/algeria-venture-djezzy-and-taubyte-launch-ai-development-platform-aventurecloudz/ | O33: Verified | P33: Cross-checked with official ac.dz and Telecompaper. [Reclassified 2026-08-01] Old Sector: 'Enterprise AI' -> New: 'Industry'. Old Entity Type: 'Hub' -> New Ecosystem Type: 'Other initiatives'. [Refined 2026-08-02] Sector set to 'Industry'. Maturity inferred as 'Early' (default for Startup/R&D with no funding signal).
A34: Algeria | B34: Education | C34: Virtual education & AI pedagogy center | D34: Other initiatives | E34: Early | F34: Centre de Technologie et d'Innovation en Systèmes d'Éducation Virtuelle (Sidi Abdallah) | G34: Algeria's first national center for technologies and innovation in virtual education systems, inaugurated 8 June 2026 at the Abdelhafid Ihaddaden scientific hub (Sidi Abdallah) by Higher Education Minister Kamel Baddari with Prof. Elias Zerhouni (project designer); provides AI-powered multilingual distance-learning platforms for a 'fourth-generation university' model. | H34: Government program | I34: 2026-06-08 | J34: 2026-08-05 | L34: Algerie360 / We Are Tech Africa | M34: Primary (News) | N34: https://www.algerie360.com/education-et-ia-lalgerie-inaugure-son-premier-centre-dapprentissage-virtuel-a-sidi-abdallah/ | O34: Verified | P34: Cross-checked two independent press reports (Algerie360, We Are Tech Africa) plus Algérie Eco and El Watan coverage of the 8 June 2026 inauguration. [Added 2026-08-05 expansion pass]
A35: Algeria | B35: Industry | C35: Telecom AI Adoption & Partnerships | D35: Other initiatives | E35: Early | F35: Djezzy (AI initiatives) | G35: Telecom operator building AI capability: ENSIA partnership (Dec 2024) for AI projects, cloud launch, open-innovation deals with Algerian AI startups (AI Grid, Capture-Doc, Intadj) and the AventureCloudz platform. | H35: News article | I35: 2024-12 | J35: 2026-07-22 | L35: Algerie Eco | M35: Primary (News) | N35: https://algerie-eco.com/2024/12/23/djezzy-sengage-dans-lere-de-lintelligence-artificielle-en-partenariat-avec-lensia/ | O35: Verified | P35: Cross-checked with TSA; covers Djezzy as corporate actor (ENSIA already in DB). [Reclassified 2026-08-01] Old Sector: 'Enterprise AI' -> New: 'Industry'. Old Entity Type: 'Hub' -> New Ecosystem Type: 'Other initiatives'. [Refined 2026-08-02] Sector set to 'Industry'. Maturity inferred as 'Early' (default for Startup/R&D with no funding signal).
A36: Algeria | B36: Energy | C36: AI for oil & gas - academia-industry link | D36: Other initiatives | E36: Early | F36: ENSIA-Sonatrach 'AI in Oil & Gas' industry engagement | G36: Open-house partnership day (12 February 2024) at the National Higher School of AI (ENSIA) with Sonatrach, InnoDevData and Qareeb, where Sonatrach presented the future of AI applications in the oil and gas sector and recruited student engagement, formalizing an energy-sector pipeline for Algeria's AI school. | H36: Partnership announcement | I36: 2024-02-12 | J36: 2026-08-05 | L36: ENSIA | M36: Primary | N36: https://www.ensia.edu.dz/fr/exploring-ai-applications-in-oil-and-gas-sector/ | O36: Verified | P36: Read directly on ENSIA's official website news page naming Sonatrach and the participating companies. [Added 2026-08-05 expansion pass]
... A70: Algeria | B70: Education | C70: AI & Data Science Degree Programs | D70: R&D | E70: Established | F70: Universite Constantine 2 - Faculte NTIC | G70: Dedicated ICT faculty offering Master programs in Data Science & Artificial Intelligence (DSIA) and Data Science & Intelligent Systems; hosts AI-active research labs (e.g. MISC). | H70: Master admissions page | I70: 2024-06 | J70: 2026-07-22 | L70: Faculte NTIC, Universite Constantine 2 (official) | M70: Primary | N70: https://facntic.univ-constantine2.dz/2024/06/28/candidatures-master-2024-2025/ | O70: Verified | P70: Official faculty page lists both AI/data-science masters. [Reclassified 2026-08-01] Old Sector: 'General' -> New: 'Education'. Old Entity Type: 'Hub' -> New Ecosystem Type: 'R&D'. [Refined 2026-08-02] Sector set to 'Industry'. Maturity inferred as 'Early' (default for Startup/R&D with no funding signal). [Audit 2026-08-05] Sector corrected: 'Industry' -> 'Education'. [Audit 2026-08-05] Reason: university faculty with degree programs [Audit 2026-08-05] Maturity corrected: 'Early' -> 'Established'. [Audit 2026-08-05] Reason: institutional R&D entity (established university faculty); the blanket Early default under-stated organizational maturity
A71: Algeria | B71: Energy | C71: Sovereign GPU/AI Cloud | D71: Startup | E71: Early | F71: AI Grid | G71: Algerian startup building sovereign, energy-efficient GPU/AI cloud infrastructure (founded by an ex-Microsoft AI speech scientist); conventions signed with Etihad Groupe at ASC (Dec 2025); works with Djezzy on AI solutions. | H71: News article | I71: 2025-12 | J71: 2026-07-22 | K71: Undisclosed | L71: Algerie Patriotique | M71: Primary (News) | N71: https://algeriepatriotique.com/2025/12/09/cybersecurite-intelligence-artificielle-et-economie-bleue-des-conventions-signees-entre-startups-et-entreprises/ | O71: Verified | P71: [Reclassified 2026-08-01] Old Sector: 'Agritech' -> New: 'Energy'. Old Entity Type: 'Startup' -> New Ecosystem Type: 'Startup'. [Refined 2026-08-02] Sector set to 'Energy'. Maturity inferred as 'Early' (default for Startup/R&D with no funding signal).
A72: Algeria | B72: Industry | C72: Applied AI / RAG | D72: Startup | E72: Early | F72: BADIS AI | G72: Sovereign-AI software editor at the Cyberparc of Sidi Abdellah (Algiers) offering OCR, RAG, AI agents and Arabic/Darija chatbots. | H72: Company profile | I72: Not specified | J72: 2026-07-22 | K72: Undisclosed | L72: BADIS AI (official) | M72: Primary | N72: https://badis.ai/ | O72: Verified | P72: [Reclassified 2026-08-01] Old Sector: 'Enterprise AI' -> New: 'Industry'. Old Entity Type: 'Startup' -> New Ecosystem Type: 'Startup'. [Refined 2026-08-02] Sector set to 'Industry'. Maturity inferred as 'Early' (default for Startup/R&D with no funding signal).
A73: Algeria | B73: Industry | C73: Fire-safety robotics | D73: Startup | E73: Early | F73: BK Fire (Icosium firefighting robot) | G73: Algiers-based fire-safety company (founded 2008, repositioned as deeptech) that developed 'Icosium', a locally built firefighting robot designed to operate in high-temperature environments too dangerous for humans, one of Algeria's few hardware-robotics ventures. | H73: Company profile | I73: 2026 | J73: 2026-08-05 | K73: Undisclosed | L73: Mag Startup | M73: Aggregator | N73: https://www.magstartup.com/10-startups-algeriennes-a-suivre-en-2026-au-dela-du-bruit/ | O73: Not yet verified | P73: Found in Mag Startup's 2026 Algerian startup roundup only; robot name and repositioning not yet cross-checked with a primary source. [Added 2026-08-05 expansion pass]
...

Sheet Summary
A1: Metric | B1: Count
A2: Total records | B2: =COUNTA(Dataset!A2:A638) -> 637
A4: By verification status
A5: Verified | B5: =COUNTIF(Dataset!O2:O638,"Verified") -> 565
A6: Not yet verified | B6: =COUNTIF(Dataset!O2:O638,"Not yet verified") -> 71
A7: Mismatch found | B7: =COUNTIF(Dataset!O2:O638,"Mismatch found") -> 1
A9: By country - southern shore
A10: Algeria | B10: =COUNTIF(Dataset!A2:A638,"Algeria") -> 93
A11: Egypt | B11: =COUNTIF(Dataset!A2:A638,"Egypt") -> 142
A12: Lebanon | B12: =COUNTIF(Dataset!A2:A638,"Lebanon") -> 78
A13: Morocco | B13: =COUNTIF(Dataset!A2:A638,"Morocco") -> 113
A14: Tunisia | B14: =COUNTIF(Dataset!A2:A638,"Tunisia") -> 111
A16: By country - northern shore
A17: France | B17: =COUNTIF(Dataset!A2:A638,"France") -> 40
A18: Italy | B18: =COUNTIF(Dataset!A2:A638,"Italy") -> 30
A19: Spain | B19: =COUNTIF(Dataset!A2:A638,"Spain") -> 30
A21: By sector
A22: Agriculture | B22: =COUNTIF(Dataset!B2:B638,"Agriculture") -> 41
A23: Education | B23: =COUNTIF(Dataset!B2:B638,"Education") -> 122
A24: Energy | B24: =COUNTIF(Dataset!B2:B638,"Energy") -> 22
A25: Health | B25: =COUNTIF(Dataset!B2:B638,"Health") -> 48
A26: Industry | B26: =COUNTIF(Dataset!B2:B638,"Industry") -> 390
A27: Maritime | B27: =COUNTIF(Dataset!B2:B638,"Maritime") -> 14
A29: By entity type
A30: Community/Association | B30: =COUNTIF(Dataset!D2:D638,"Community/Association") -> 19
A31: Conference/Summit | B31: =COUNTIF(Dataset!D2:D638,"Conference/Summit") -> 29
A32: Funding | B32: =COUNTIF(Dataset!D2:D638,"Funding") -> 47
A33: Hackathons | B33: =COUNTIF(Dataset!D2:D638,"Hackathons") -> 24
A34: Incubator/Accelerator | B34: =COUNTIF(Dataset!D2:D638,"Incubator/Accelerator") -> 52
A35: Other initiatives | B35: =COUNTIF(Dataset!D2:D638,"Other initiatives") -> 57
A36: Policy/Strategy | B36: =COUNTIF(Dataset!D2:D638,"Policy/Strategy") -> 84
A37: R&D | B37: =COUNTIF(Dataset!D2:D638,"R&D") -> 93
A38: Startup | B38: =COUNTIF(Dataset!D2:D638,"Startup") -> 232
A40: Maturity recorded | B40: =COUNTA(Dataset!E2:E638) -> 521

Sheet Charts
A1: Records by country
A2: Category | B2: Count
A3: Italy | B3: 30
A4: Spain | B4: 30
A5: France | B5: 40
A6: Lebanon | B6: 78
A7: Algeria | B7: 93
A8: Tunisia | B8: 111
A9: Morocco | B9: 113
A10: Egypt | B10: 142
A12: Records by entity type
A13: Category | B13: Count
A14: Community/Association | B14: 19
A15: Hackathons | B15: 24
A16: Conference/Summit | B16: 29
A17: Funding | B17: 47
A18: Incubator/Accelerator | B18: 52
A19: Other initiatives | B19: 57
A20: Policy/Strategy | B20: 84
A21: R&D | B21: 93
A22: Startup | B22: 232
A25: Records by sector
A26: Category | B26: Count
A27: Maritime | B27: 14
A28: Energy | B28: 22
A29: Agriculture | B29: 41
A30: Health | B30: 48
A31: Education | B31: 122
A32: Industry | B32: 390
A35: Records by source type
A36: Category | B36: Count
A37: Primary | B37: 218
A38: Primary (News) | B38: 214
A39: Aggregator | B39: 79
A40: Primary (Government) | B40: 54
A41: Secondary | B41: 52
A42: Aggregator (Intergovernmental) | B42: 6
A43: Primary (Intergovernmental) | B43: 5
A44: Secondary (Academic Survey) | B44: 4
A45: Primary (EU) | B45: 4
...

Sheet Change Log
A1: Change | B1: Detail
A2: Merge of the two dataset branches | B2: The five-country dataset (521 records) and the northern-Mediterranean extension (476 records) were two branches sharing 360 records, not successive versions. They were merged into a single dataset of 637 records covering eight countries. 161 records existed only in the five-country branch and 116 only in the extension (100 European plus 16 Lebanese policy and ecosystem records).
A3: Schema retained | B3: The five-country schema was kept as canonical: nine entity types, a Maturity column, and a six-value Sector column recording the application domain served. It carries more information than the extension's four entity types.
A4: Sector mapping applied to incoming records | B4: The extension's Application Sector was mapped onto the six-value Sector: Industry, Education, Agriculture, Energy and Maritime map directly; Healthcare maps to Health. Finance, Government and Cross-sector have no equivalent and were resolved per record from the technology sector and sub-sector, defaulting to Industry. This follows the existing convention, under which 31 of 38 funding records and 36 of 53 policy records were already filed as Industry. Result: 86 to Industry, 22 to Education, 8 to Health.
A5: Entity type mapping applied to incoming records | B5: Startup maps directly; Investor becomes Funding; Policy becomes Policy/Strategy. Hub was split by sub-sector: incubators and campuses to Incubator/Accelerator, research centres, supercomputing and language-model work to R&D, communities and associations to Community/Association, events to Conference/Summit, infrastructure and foundations to Other initiatives.
A6: Maturity left blank for merged records | B6: The extension did not record maturity. Rather than infer it, the 116 merged records carry a blank Maturity value, flagged in the dataset quality report. 521 of 637 records have maturity recorded.
A7: Provenance recorded per record | B7: Every merged record's Notes field records its original sector, application sector and entity type, so the mapping is reversible and auditable.
A8: Verification convention unchanged | B8: Verified records are shaded green, Not yet verified are unshaded, Mismatch found is shaded red and excluded from the search index. Current split: 565 verified, 71 not yet verified, 1 mismatch.
